Workbook

Sheet OVN Audiences
A2: x
A3: x
A4: x
A5: x
A6: x
A7: x
A8: x | Q8: All Individuals 4+ (1 Minute) | U8: Men 16-34 (1 Minute) | Y8: Adults 16+ (1 Minute)
A9: Type | B9: Competition | C9: Home Team | D9: Away Team | E9: Type of programme | F9: Time slot | G9: TV Package | H9: Date | I9: Season | J9: Day | K9: Programme Title | L9: Channel | M9: Broadcaster | N9: Start Time | O9: End Time | P9: Duration | Q9: 000's | R9: TVR | S9: Share | T9: Peak | U9: 000's | V9: TVR | W9: Share | X9: Peak | Y9: 000's | Z9: TVR | AA9: Share | AB9: Peak | AC9: OTT Total Audience | AD9: PC/Laptop | AE9: Tablet | AF9: Smart Phone | AG9: Match Type | AH9: Matchweek
A10: OVN | B10: Scottish Premiership | C10: Motherwell | D10: Rangers | E10: Live | F10: 0.72916667 | H10: 45871 | I10: 2025/26 | J10: Sat | K10: Whistle-to-Whistle | L10: Sky Sports Main Event | M10: Sky Sports | N10: 0.72916667 | O10: 0.80694444 | P10: 0.077777778 | Q10: 173.3 | R10: 0.281 | S10: 2.139 | T10: 242.8 | U10: 13.9 | V10: 0.191 | W10: 6.891 | X10: 40.2 | Y10: 171.5 | Z10: 0.325 | AA10: 2.188 | AB10: 237.2 | AH10: =IF(AND(B10="Premier League",E10="Live"),_xlfn.XLOOKUP(_xlfn.TEXTJOIN(" vs ",,C10:D10),Calendar!G:G,Calendar!B:B),IF(AND(B10="Premier League",E10="Highlights"),_xlfn.XLOOKUP(H10,Calendar!O:O,Calendar!N:N,,-1),""))
A11: OVN | B11: Scottish Premiership | C11: Motherwell | D11: Rangers | E11: Live | F11: 0.72916667 | H11: 45871 | I11: 2025/26 | J11: Sat | K11: Whistle-to-Whistle | L11: Sky Sports Football | M11: Sky Sports | N11: 0.72916667 | O11: 0.80694444 | P11: 0.077777778 | Q11: 97.5 | R11: 0.158 | S11: 1.204 | T11: 136.7 | U11: 14.2 | V11: 0.195 | W11: 7.04 | X11: 23.7 | Y11: 95.8 | Z11: 0.182 | AA11: 1.222 | AB11: 134.9 | AH11: =IF(AND(B11="Premier League",E11="Live"),_xlfn.XLOOKUP(_xlfn.TEXTJOIN(" vs ",,C11:D11),Calendar!G:G,Calendar!B:B),IF(AND(B11="Premier League",E11="Highlights"),_xlfn.XLOOKUP(H11,Calendar!O:O,Calendar!N:N,,-1),""))
A12: OVN | B12: Sky Bet League One | C12: Stockport County | D12: Bolton Wanderers | E12: Live | F12: 0.5 | H12: 45872 | I12: 2025/26 | J12: Sun | K12: Whistle-to-Whistle | L12: Sky Sports Football | M12: Sky Sports | N12: 0.5 | O12: 0.53333333 | P12: 0.033333333 | Q12: 98.6 | R12: 0.16 | S12: 1.967 | T12: 120.8 | U12: 13.5 | V12: 0.186 | W12: 8.432 | X12: 15.3 | Y12: 89.3 | Z12: 0.169 | AA12: 1.836 | AB12: 111.5 | AH12: =IF(AND(B12="Premier League",E12="Live"),_xlfn.XLOOKUP(_xlfn.TEXTJOIN(" vs ",,C12:D12),Calendar!G:G,Calendar!B:B),IF(AND(B12="Premier League",E12="Highlights"),_xlfn.XLOOKUP(H12,Calendar!O:O,Calendar!N:N,,-1),""))
A13: OVN | B13: Scottish Premiership | C13: Falkirk | D13: Dundee United | E13: Live | F13: 0.58333333 | H13: 45872 | I13: 2025/26 | J13: Sun | K13: Whistle-to-Whistle | L13: Sky Sports Football | M13: Sky Sports | N13: 0.58333333 | O13: 0.6625 | P13: 0.079166667 | Q13: 82.7 | R13: 0.134 | S13: 1.226 | T13: 160 | U13: 10.9 | V13: 0.15 | W13: 4.39 | X13: 19.2 | Y13: 82 | Z13: 0.156 | AA13: 1.251 | AB13: 156.8 | AH13: =IF(AND(B13="Premier League",E13="Live"),_xlfn.XLOOKUP(_xlfn.TEXTJOIN(" vs ",,C13:D13),Calendar!G:G,Calendar!B:B),IF(AND(B13="Premier League",E13="Highlights"),_xlfn.XLOOKUP(H13,Calendar!O:O,Calendar!N:N,,-1),""))
A14: OVN | B14: Scottish Premiership | C14: Celtic | D14: St Mirren | E14: Live | F14: 0.6875 | H14: 45872 | I14: 2025/26 | J14: Sun | K14: Whistle-to-Whistle | L14: Sky Sports Main Event | M14: Sky Sports | N14: 0.68958333 | O14: 0.76875 | P14: 0.079166667 | Q14: 115.3 | R14: 0.187 | S14: 1.389 | T14: 193 | U14: 13.2 | V14: 0.182 | W14: 6.647 | X14: 23.8 | Y14: 113 | Z14: 0.214 | AA14: 1.397 | AB14: 187.5 | AH14: =IF(AND(B14="Premier League",E14="Live"),_xlfn.XLOOKUP(_xlfn.TEXTJOIN(" vs ",,C14:D14),Calendar!G:G,Calendar!B:B),IF(AND(B14="Premier League",E14="Highlights"),_xlfn.XLOOKUP(H14,Calendar!O:O,Calendar!N:N,,-1),""))
A15: OVN | B15: Scottish Premiership | C15: Celtic | D15: St Mirren | E15: Live | F15: 0.6875 | H15: 45872 | I15: 2025/26 | J15: Sun | K15: Whistle-to-Whistle | L15: Sky Sports Football | M15: Sky Sports | N15: 0.68958333 | O15: 0.76875 | P15: 0.079166667 | Q15: 137.9 | R15: 0.223 | S15: 1.661 | T15: 201.6 | U15: 1.8 | V15: 0.025 | W15: 0.906 | X15: 26.3 | Y15: 136.5 | Z15: 0.259 | AA15: 1.688 | AB15: 201.6 | AH15: =IF(AND(B15="Premier League",E15="Live"),_xlfn.XLOOKUP(_xlfn.TEXTJOIN(" vs ",,C15:D15),Calendar!G:G,Calendar!B:B),IF(AND(B15="Premier League",E15="Highlights"),_xlfn.XLOOKUP(H15,Calendar!O:O,Calendar!N:N,,-1),""))
A16: OVN | B16: Scottish Premiership | C16: Hearts | D16: Aberdeen | E16: Live | F16: 0.83333333 | H16: 45873 | I16: 2025/26 | J16: Mon | K16: Whistle-to-Whistle | L16: Sky Sports Main Event | M16: Sky Sports | N16: 0.83333333 | O16: 0.91319444 | P16: 0.079861111 | Q16: 101.9 | R16: 0.165 | S16: 0.959 | T16: 159.9 | U16: 6 | V16: 0.083 | W16: 2.75 | X16: 17.5 | Y16: 98.8 | Z16: 0.187 | AA16: 0.951 | AB16: 157.8 | AH16: =IF(AND(B16="Premier League",E16="Live"),_xlfn.XLOOKUP(_xlfn.TEXTJOIN(" vs ",,C16:D16),Calendar!G:G,Calendar!B:B),IF(AND(B16="Premier League",E16="Highlights"),_xlfn.XLOOKUP(H16,Calendar!O:O,Calendar!N:N,,-1),""))
A17: OVN | B17: Scottish Premiership | C17: Hearts | D17: Aberdeen | E17: Live | F17: 0.83333333 | H17: 45873 | I17: 2025/26 | J17: Mon | K17: Whistle-to-Whistle | L17: Sky Sports Football | M17: Sky Sports | N17: 0.83333333 | O17: 0.91319444 | P17: 0.079861111 | Q17: 90.5 | R17: 0.147 | S17: 0.852 | T17: 115.4 | U17: 0.1 | V17: 0.001 | W17: 0.046 | X17: 2.8 | Y17: 89.1 | Z17: 0.169 | AA17: 0.857 | AB17: 112.1 | AH17: =IF(AND(B17="Premier League",E17="Live"),_xlfn.XLOOKUP(_xlfn.TEXTJOIN(" vs ",,C17:D17),Calendar!G:G,Calendar!B:B),IF(AND(B17="Premier League",E17="Highlights"),_xlfn.XLOOKUP(H17,Calendar!O:O,Calendar!N:N,,-1),""))
A18: OVN | B18: Carabao Cup | C18: Accrington Stanley | D18: Oldham Athletic | E18: Live | F18: 0.82291667 | H18: 45874 | I18: 2025/26 | J18: Tue | K18: Whistle-to-Whistle | L18: Sky Sports Plus | M18: Sky Sports | N18: 0.82291667 | O18: 0.90277778 | P18: 0.079861111 | Q18: 5.4 | R18: 0.009 | S18: 0.051 | T18: 17.8 | U18: 0.1 | V18: 0.001 | W18: 0.05 | X18: 2.2 | Y18: 5.3 | Z18: 0.01 | AA18: 0.051 | AB18: 17.8 | AH18: =IF(AND(B18="Premier League",E18="Live"),_xlfn.XLOOKUP(_xlfn.TEXTJOIN(" vs ",,C18:D18),Calendar!G:G,Calendar!B:B),IF(AND(B18="Premier League",E18="Highlights"),_xlfn.XLOOKUP(H18,Calendar!O:O,Calendar!N:N,,-1),""))
A19: OVN | B19: UEFA Champions League | C19: Rangers | D19: Viktoria-plzen | E19: Live | F19: 0.82291667 | H19: 45874 | I19: 2025/26 | J19: Tue | K19: Whistle-to-Whistle | L19: BBC Scotland | M19: BBC | N19: 0.82291667 | O19: 0.90138889 | P19: 0.078472222 | Q19: 12.5 | R19: 0.02 | S19: 0.118 | T19: 32.4 | U19: 0 | V19: 0 | W19: 0 | X19: - | Y19: 12.5 | Z19: 0.024 | AA19: 0.121 | AB19: 32.4 | AH19: =IF(AND(B19="Premier League",E19="Live"),_xlfn.XLOOKUP(_xlfn.TEXTJOIN(" vs ",,C19:D19),Calendar!G:G,Calendar!B:B),IF(AND(B19="Premier League",E19="Highlights"),_xlfn.XLOOKUP(H19,Calendar!O:O,Calendar!N:N,,-1),""))
A20: OVN | B20: Sky Bet League One | C20: Port Vale | D20: Cardiff City | E20: Live | F20: 0.83333333 | H20: 45876 | I20: 2025/26 | J20: Thu | K20: Whistle-to-Whistle | L20: Sky Sports Football | M20: Sky Sports | N20: 0.83333333 | O20: 0.91319444 | P20: 0.079861111 | Q20: 55.2 | R20: 0.089 | S20: 0.545 | T20: 88 | U20: 5.2 | V20: 0.072 | W20: 2.805 | X20: 11.7 | Y20: 50.8 | Z20: 0.096 | AA20: 0.515 | AB20: 84.2 | AH20: =IF(AND(B20="Premier League",E20="Live"),_xlfn.XLOOKUP(_xlfn.TEXTJOIN(" vs ",,C20:D20),Calendar!G:G,Calendar!B:B),IF(AND(B20="Premier League",E20="Highlights"),_xlfn.XLOOKUP(H20,Calendar!O:O,Calendar!N:N,,-1),""))
A21: OVN | B21: UEFA Europa Conference League | C21: Rapid Vienna | D21: Dundee United | E21: Live | F21: 0.83333333 | H21: 45876 | I21: 2025/26 | J21: Thu | K21: Whistle-to-Whistle | L21: BBC Scotland | M21: BBC | N21: 0.83333333 | O21: 0.91666667 | P21: 0.083333333 | Q21: 171.6 | R21: 0.278 | S21: 1.7 | T21: 232.5 | U21: 8.4 | V21: 0.116 | W21: 4.506 | X21: 16.6 | Y21: 167.3 | Z21: 0.317 | AA21: 1.701 | AB21: 228.9 | AH21: =IF(AND(B21="Premier League",E21="Live"),_xlfn.XLOOKUP(_xlfn.TEXTJOIN(" vs ",,C21:D21),Calendar!G:G,Calendar!B:B),IF(AND(B21="Premier League",E21="Highlights"),_xlfn.XLOOKUP(H21,Calendar!O:O,Calendar!N:N,,-1),""))
A22: OVN | B22: Sky Bet League One | C22: Port Vale | D22: Cardiff City | E22: Live | F22: 0.83333333 | H22: 45876 | I22: 2025/26 | J22: Thu | K22: Whistle-to-Whistle | L22: Sky Sports Main Event | M22: Sky Sports | N22: 0.83333333 | O22: 0.91319444 | P22: 0.079861111 | Q22: 89.9 | R22: 0.1 | S22: 0.8881 | T22: 158.8 | U22: 3.5 | V22: 0 | W22: 1.8878 | X22: 9.2 | Y22: 85.6 | Z22: 0.2 | AA22: 0.8682 | AB22: 155.9 | AH22: =IF(AND(B22="Premier League",E22="Live"),_xlfn.XLOOKUP(_xlfn.TEXTJOIN(" vs ",,C22:D22),Calendar!G:G,Calendar!B:B),IF(AND(B22="Premier League",E22="Highlights"),_xlfn.XLOOKUP(H22,Calendar!O:O,Calendar!N:N,,-1),""))
A23: OVN | B23: Sky Bet League One | C23: Port Vale | D23: Cardiff City | E23: Live | F23: 0.83333333 | H23: 45876 | I23: 2025/26 | J23: Thu | K23: Whistle-to-Whistle | L23: Sky Sports Football | M23: Sky Sports | N23: 0.83333333 | O23: 0.91319444 | P23: 0.079861111 | Q23: 55.2 | R23: 0.1 | S23: 0.5453 | T23: 88 | U23: 5.2 | V23: 0.1 | W23: 2.8047 | X23: 11.7 | Y23: 50.8 | Z23: 0.1 | AA23: 0.5153 | AB23: 84.2 | AH23: =IF(AND(B23="Premier League",E23="Live"),_xlfn.XLOOKUP(_xlfn.TEXTJOIN(" vs ",,C23:D23),Calendar!G:G,Calendar!B:B),IF(AND(B23="Premier League",E23="Highlights"),_xlfn.XLOOKUP(H23,Calendar!O:O,Calendar!N:N,,-1),""))
A24: OVN | B24: Scottish Championship | C24: Ross County | D24: St Johnstone | E24: Live | F24: 0.82291667 | H24: 45877 | I24: 2025/26 | J24: Fri | K24: Whistle-to-Whistle | L24: BBC Scotland | M24: BBC | N24: 0.82430556 | O24: 0.90208333 | P24: 0.077777778 | Q24: 71.1 | R24: 0.115 | S24: 0.713 | T24: 134.2 | U24: 18.7 | V24: 0.257 | W24: 7.474 | X24: 28.6 | Y24: 69.9 | Z24: 0.133 | AA24: 0.719 | AB24: 130.6 | AH24: =IF(AND(B24="Premier League",E24="Live"),_xlfn.XLOOKUP(_xlfn.TEXTJOIN(" vs ",,C24:D24),Calendar!G:G,Calendar!B:B),IF(AND(B24="Premier League",E24="Highlights"),_xlfn.XLOOKUP(H24,Calendar!O:O,Calendar!N:N,,-1),""))
A25: OVN | B25: Sky Bet Championship | C25: Birmingham City | D25: Ipswich Town | E25: Live | F25: 0.83333333 | H25: 45877 | I25: 2025/26 | J25: Fri | K25: Whistle-to-Whistle | L25: Sky Sports Main Event | M25: Sky Sports | N25: 0.83402778 | O25: 0.91597222 | P25: 0.081944444 | Q25: 390.5 | R25: 0.6 | S25: 3.9581 | T25: 510.4 | U25: 43.2 | V25: 0.6 | W25: 17.4757 | X25: 62.6 | Y25: 383.8 | Z25: 0.7 | AA25: 3.9841 | AB25: 502 | AH25: =IF(AND(B25="Premier League",E25="Live"),_xlfn.XLOOKUP(_xlfn.TEXTJOIN(" vs ",,C25:D25),Calendar!G:G,Calendar!B:B),IF(AND(B25="Premier League",E25="Highlights"),_xlfn.XLOOKUP(H25,Calendar!O:O,Calendar!N:N,,-1),""))
A26: OVN | B26: Sky Bet Championship | C26: Birmingham City | D26: Ipswich Town | E26: Live | F26: 0.83333333 | H26: 45877 | I26: 2025/26 | J26: Fri | K26: Whistle-to-Whistle | L26: Sky Sports Football | M26: Sky Sports | N26: 0.83402778 | O26: 0.91597222 | P26: 0.081944444 | Q26: 127.3 | R26: 0.2 | S26: 1.2903 | T26: 180.1 | U26: 14.7 | V26: 0.2 | W26: 5.9466 | X26: 24.3 | Y26: 117.2 | Z26: 0.2 | AA26: 1.2166 | AB26: 167.1 | AH26: =IF(AND(B26="Premier League",E26="Live"),_xlfn.XLOOKUP(_xlfn.TEXTJOIN(" vs ",,C26:D26),Calendar!G:G,Calendar!B:B),IF(AND(B26="Premier League",E26="Highlights"),_xlfn.XLOOKUP(H26,Calendar!O:O,Calendar!N:N,,-1),""))
A27: OVN | B27: Sky Bet Championship | C27: Coventry City | D27: Hull City | E27: Live | F27: 0.52083333 | H27: 45878 | I27: 2025/26 | J27: Sat | K27: Whistle-to-Whistle | L27: Sky Sports + | M27: Sky Sports | N27: 0.52152778 | O27: 0.60208333 | P27: 0.080555556 | Q27: 66.2 | R27: 0.107 | S27: 1.415 | T27: 87.4 | U27: 3 | V27: 0.041 | W27: 2.182 | X27: 3.7 | Y27: 66.2 | Z27: 0.126 | AA27: 1.464 | AB27: 87.4 | AH27: =IF(AND(B27="Premier League",E27="Live"),_xlfn.XLOOKUP(_xlfn.TEXTJOIN(" vs ",,C27:D27),Calendar!G:G,Calendar!B:B),IF(AND(B27="Premier League",E27="Highlights"),_xlfn.XLOOKUP(H27,Calendar!O:O,Calendar!N:N,,-1),""))
A28: OVN | B28: Sky Bet Championship | C28: Southampton | D28: Wrexham | E28: Live | F28: 0.52083333 | H28: 45878 | I28: 2025/26 | J28: Sat | K28: Whistle-to-Whistle | L28: Sky Sports Main Event | M28: Sky Sports | N28: 0.52083333 | O28: 0.60208333 | P28: 0.08125 | Q28: 359.6 | R28: 0.582 | S28: 7.691 | T28: 502.1 | U28: 41.2 | V28: 0.567 | W28: 30.007 | X28: 51.9 | Y28: 350.2 | Z28: 0.664 | AA28: 7.75 | AB28: 483.7 | AH28: =IF(AND(B28="Premier League",E28="Live"),_xlfn.XLOOKUP(_xlfn.TEXTJOIN(" vs ",,C28:D28),Calendar!G:G,Calendar!B:B),IF(AND(B28="Premier League",E28="Highlights"),_xlfn.XLOOKUP(H28,Calendar!O:O,Calendar!N:N,,-1),""))
A29: OVN | B29: Sky Bet Championship | C29: Southampton | D29: Wrexham | E29: Live | F29: 0.52083333 | H29: 45878 | I29: 2025/26 | J29: Sat | K29: Whistle-to-Whistle | L29: Sky Sports Football | M29: Sky Sports | N29: 0.52083333 | O29: 0.60208333 | P29: 0.08125 | Q29: 174.6 | R29: 0.283 | S29: 3.734 | T29: 234 | U29: 11.5 | V29: 0.158 | W29: 8.376 | X29: 26.7 | Y29: 171.6 | Z29: 0.326 | AA29: 3.798 | AB29: 232 | AH29: =IF(AND(B29="Premier League",E29="Live"),_xlfn.XLOOKUP(_xlfn.TEXTJOIN(" vs ",,C29:D29),Calendar!G:G,Calendar!B:B),IF(AND(B29="Premier League",E29="Highlights"),_xlfn.XLOOKUP(H29,Calendar!O:O,Calendar!N:N,,-1),""))
A30: OVN | B30: Sky Bet Championship | C30: West Brom | D30: Blackburn Rovers | E30: Live | F30: 0.625 | H30: 45878 | I30: 2025/26 | J30: Sat | K30: Whistle-to-Whistle | L30: Sky Sports + | M30: Sky Sports | N30: 0.62569444 | O30: 0.70833333 | P30: 0.082638889 | Q30: 109.5 | R30: 0.177 | S30: 2.176 | T30: 157.6 | U30: 2.3 | V30: 0.032 | W30: 1.934 | X30: 2.7 | Y30: 105 | Z30: 0.199 | AA30: 2.162 | AB30: 152.4 | AH30: =IF(AND(B30="Premier League",E30="Live"),_xlfn.XLOOKUP(_xlfn.TEXTJOIN(" vs ",,C30:D30),Calendar!G:G,Calendar!B:B),IF(AND(B30="Premier League",E30="Highlights"),_xlfn.XLOOKUP(H30,Calendar!O:O,Calendar!N:N,,-1),""))
A31: OVN | B31: Scottish Premiership | C31: Rangers | D31: Dundee | E31: Live | F31: 0.73958333 | H31: 45878 | I31: 2025/26 | J31: Sat | K31: Whistle-to-Whistle | L31: Premier Sports 1 | M31: Premier Sports | N31: 0.73888889 | O31: 0.81944444 | P31: 0.080555556 | Q31: 104.9 | R31: 0.17 | S31: 1.245 | T31: 131 | U31: 3.4 | V31: 0.047 | W31: 2.129 | X31: 3.5 | Y31: 104.9 | Z31: 0.199 | AA31: 1.276 | AB31: 131 | AH31: =IF(AND(B31="Premier League",E31="Live"),_xlfn.XLOOKUP(_xlfn.TEXTJOIN(" vs ",,C31:D31),Calendar!G:G,Calendar!B:B),IF(AND(B31="Premier League",E31="Highlights"),_xlfn.XLOOKUP(H31,Calendar!O:O,Calendar!N:N,,-1),""))
... A37: OVN | B37: Sky Bet Championship | C37: Leicester City | D37: Sheffield Wednesday | E37: Live | F37: 0.6875 | H37: 45879 | I37: 2025/26 | J37: Sun | K37: Whistle-to-Whistle | L37: Sky Sports Football | M37: Sky Sports | N37: 0.6875 | O37: 0.77013889 | P37: 0.082638889 | Q37: 204.5 | R37: 0.3 | S37: 2.6412 | T37: 278.5 | U37: 15.6 | V37: 0.2 | W37: 4.7619 | X37: 34.1 | Y37: 186.9 | Z37: 0.4 | AA37: 2.494 | AB37: 253.1 | AH37: =IF(AND(B37="Premier League",E37="Live"),_xlfn.XLOOKUP(_xlfn.TEXTJOIN(" vs ",,C37:D37),Calendar!G:G,Calendar!B:B),IF(AND(B37="Premier League",E37="Highlights"),_xlfn.XLOOKUP(H37,Calendar!O:O,Calendar!N:N,,-1),""))
A38: OVN | B38: Carabao Cup | C38: West Brom | D38: Derby County | E38: Live | F38: 0.82291667 | H38: 45881 | I38: 2025/26 | J38: Tue | K38: Whistle-to-Whistle | L38: Sky Sports + | M38: Sky Sports | N38: 0.82361111 | O38: 0.9125 | P38: 0.088888889 | AH38: =IF(AND(B38="Premier League",E38="Live"),_xlfn.XLOOKUP(_xlfn.TEXTJOIN(" vs ",,C38:D38),Calendar!G:G,Calendar!B:B),IF(AND(B38="Premier League",E38="Highlights"),_xlfn.XLOOKUP(H38,Calendar!O:O,Calendar!N:N,,-1),""))
A39: OVN | B39: Carabao Cup | C39: Bromley | D39: Ipswich Town | E39: Live | F39: 0.83333333 | H39: 45881 | I39: 2025/26 | J39: Tue | K39: Whistle-to-Whistle | L39: Sky Sports Football | M39: Sky Sports | N39: 0.83333333 | O39: 0.91944444 | P39: 0.086111111 | Q39: 31.5 | R39: 0.051 | S39: 0.316 | T39: 73.2 | U39: 4.3 | V39: 0.059 | W39: 2.57 | X39: 16.5 | Y39: 30.5 | Z39: 0.058 | AA39: 0.313 | AB39: 69.4
A40: OVN | B40: Carabao Cup | C40: Huddersfield Town | D40: Leicester City | E40: Live | F40: 0.82291667 | H40: 45882 | I40: 2025/26 | J40: Wed | K40: Whistle-to-Whistle | L40: Sky Sports + | M40: Sky Sports | N40: 0.82291667 | O40: 0.91041667 | P40: 0.0875 | Q40: 95.8 | R40: 0.155 | S40: 0.904 | T40: 143.6 | U40: 4.2 | V40: 0.058 | W40: 1.513 | X40: 11.7 | Y40: 88.1 | Z40: 0.167 | AA40: 0.85 | AB40: 129.6 | AH40: =IF(AND(B40="Premier League",E40="Live"),_xlfn.XLOOKUP(_xlfn.TEXTJOIN(" vs ",,C40:D40),Calendar!G:G,Calendar!B:B),IF(AND(B40="Premier League",E40="Highlights"),_xlfn.XLOOKUP(H40,Calendar!O:O,Calendar!N:N,,-1),""))
A41: OVN | B41: Carabao Cup | C41: Birmingham City | D41: Sheffield United | E41: Live | F41: 0.83333333 | H41: 45882 | I41: 2025/26 | J41: Wed | K41: Whistle-to-Whistle | L41: ITV 4 | M41: ITV | N41: 0.83333333 | O41: 0.91319444 | P41: 0.079861111 | Q41: 314.3 | R41: 0.509 | S41: 2.966 | T41: 387.3 | U41: 7.9 | V41: 0.109 | W41: 2.793 | X41: 30.6 | Y41: 306.8 | Z41: 0.582 | AA41: 2.96 | AB41: 382 | AH41: =IF(AND(B41="Premier League",E41="Live"),_xlfn.XLOOKUP(_xlfn.TEXTJOIN(" vs ",,C41:D41),Calendar!G:G,Calendar!B:B),IF(AND(B41="Premier League",E41="Highlights"),_xlfn.XLOOKUP(H41,Calendar!O:O,Calendar!N:N,,-1),""))
A42: OVN | B42: Carabao Cup | C42: Birmingham City | D42: Sheffield United | E42: Live | F42: 0.83333333 | H42: 45882 | I42: 2025/26 | J42: Wed | K42: Whistle-to-Whistle | L42: Sky Sports Football | M42: Sky Sports | N42: 0.83333333 | O42: 0.91319444 | P42: 0.079861111 | Q42: 58.8 | R42: 0.095 | S42: 0.555 | T42: 94 | U42: 0.1 | V42: 0.001 | W42: 0.035 | X42: 9.4 | Y42: 55.5 | Z42: 0.105 | AA42: 0.536 | AB42: 90.7 | AH42: =IF(AND(B42="Premier League",E42="Live"),_xlfn.XLOOKUP(_xlfn.TEXTJOIN(" vs ",,C42:D42),Calendar!G:G,Calendar!B:B),IF(AND(B42="Premier League",E42="Highlights"),_xlfn.XLOOKUP(H42,Calendar!O:O,Calendar!N:N,,-1),""))
A43: OVN | B43: UEFA Super Cup | C43: PSG | D43: Tottenham Hotspur | E43: Live | F43: 0.83333333 | H43: 45882 | I43: 2025/26 | J43: Wed | K43: Whistle-to-Whistle | L43: TNT Sports 1 | M43: TNT Sports | N43: 0.83472222 | O43: 0.92361111 | P43: 0.088888889 | Q43: 786.3 | R43: 1.273 | S43: 7.512 | T43: 1060.3 | U43: 133.5 | V43: 1.837 | W43: 47.24 | X43: 176.2 | Y43: 754.1 | Z43: 1.431 | AA43: 7.366 | AB43: 1021.3 | AH43: =IF(AND(B43="Premier League",E43="Live"),_xlfn.XLOOKUP(_xlfn.TEXTJOIN(" vs ",,C43:D43),Calendar!G:G,Calendar!B:B),IF(AND(B43="Premier League",E43="Highlights"),_xlfn.XLOOKUP(H43,Calendar!O:O,Calendar!N:N,,-1),""))
A44: OVN | B44: Carabao Cup | E44: Highlights | F44: 0.8125 | G44: - | H44: 45882 | I44: 2025/26 | J44: Wed | K44: Carabao Cup Highlights | L44: ITV 4 | M44: ITV | N44: 0.375 | O44: 0.43748843 | P44: 0.0625 | Q44: 60.4 | R44: 0.098 | S44: 1.625 | T44: 102.9 | U44: 2.2 | V44: 0.03 | W44: 2.138 | X44: 16.5 | Y44: 58.8 | Z44: 0.112 | AA44: 1.652 | AB44: 99.3 | AH44: =IF(AND(B44="Premier League",E44="Live"),_xlfn.XLOOKUP(_xlfn.TEXTJOIN(" vs ",,C44:D44),Calendar!G:G,Calendar!B:B),IF(AND(B44="Premier League",E44="Highlights"),_xlfn.XLOOKUP(H44,Calendar!O:O,Calendar!N:N,,-1),""))
A45: OVN | B45: UEFA Europa Conference League | C45: Hibernian | D45: Partizan Belgrade | E45: Live | F45: 0.83333333 | H45: 45883 | I45: 2025/26 | J45: Thu | K45: Whistle-to-Whistle | L45: BBC Scotland | M45: BBC | N45: 0.83472222 | O45: 0.94236111 | P45: 0.10763889 | Q45: 230.7 | R45: 0.374 | S45: 2.4443 | T45: 318.9 | U45: 8.6 | V45: 0.118 | W45: 5.0618 | X45: 39.4 | Y45: 224.1 | Z45: 0.425 | AA45: 2.4268 | AB45: 312.1 | AH45: =IF(AND(B45="Premier League",E45="Live"),_xlfn.XLOOKUP(_xlfn.TEXTJOIN(" vs ",,C45:D45),Calendar!G:G,Calendar!B:B),IF(AND(B45="Premier League",E45="Highlights"),_xlfn.XLOOKUP(H45,Calendar!O:O,Calendar!N:N,,-1),""))
A46: OVN | B46: Scottish League Cup | C46: Celtic | D46: Falkirk | E46: Live | F46: 0.82291667 | H46: 45884 | I46: 2025/26 | J46: Fri | K46: Whistle-to-Whistle | L46: Premier Sports 1 | M46: Premier Sports | N46: 0.82361111 | O46: 0.90138889 | P46: 0.077777778 | Q46: 42.6 | R46: 0.069 | S46: 0.4018 | T46: 73.2 | U46: 0.4 | V46: 0.006 | W46: 0.0847 | X46: 5.3 | Y46: 41.4 | Z46: 0.079 | AA46: 0.4021 | AB46: 70.9 | AH46: =IF(AND(B46="Premier League",E46="Live"),_xlfn.XLOOKUP(_xlfn.TEXTJOIN(" vs ",,C46:D46),Calendar!G:G,Calendar!B:B),IF(AND(B46="Premier League",E46="Highlights"),_xlfn.XLOOKUP(H46,Calendar!O:O,Calendar!N:N,,-1),""))
...

Sheet OVN Aggregated Audiences
A1: x
A2: x
A3: x
A4: x
A5: x
A6: x
A7: x
A8: x | Q8: All Individuals 4+ (1 Minute) | U8: Men 16-34 (1 Minute) | Y8: Adults 16+ (1 Minute)
A9: Type | B9: Competition | C9: Home Team | D9: Away Team | E9: Type of programme | F9: Time slot | G9: TV Package | H9: Date | I9: Season | J9: Day | K9: Programme Title | L9: Channel | M9: Broadcaster | N9: Start Time | O9: End Time | P9: Duration | Q9: 000's | R9: TVR | S9: Share | T9: Peak | U9: 000's | V9: TVR | W9: Share | X9: Peak | Y9: 000's | Z9: TVR | AA9: Share | AB9: Peak | AC9: OTT Total Audience | AD9: PC/Laptop | AE9: Tablet | AF9: Smart Phone | AG9: Match Type | AH9: Matchweek | AI9: Match ID | AJ9: MOTD ID
A10: OVN | B10: Scottish Premiership | C10: Motherwell | D10: Rangers | E10: Live | F10: 0.72916667 | H10: 45871 | I10: 2025/26 | J10: Sat | K10: Whistle-to-Whistle | L10: Sky Sports Main Event | M10: Sky Sports | N10: 0.72916667 | O10: 0.80694444 | P10: 0.077777778 | Q10: 270.8 | R10: 0.439 | S10: 3.343 | T10: 379.5 | U10: 28.1 | V10: 0.386 | W10: 13.931 | X10: 63.9 | Y10: 267.3 | Z10: 0.507 | AA10: 3.41 | AB10: 372.1 | AH10: =IF(AND(B10="Premier League",E10="Live"),_xlfn.XLOOKUP(_xlfn.TEXTJOIN(" vs ",,C10:D10),Calendar!G:G,Calendar!B:B),IF(AND(B10="Premier League",E10="Highlights"),_xlfn.XLOOKUP(H10,Calendar!O:O,Calendar!N:N,,-1),"")) | AI10: =IF(AND(AH10<>"",E10="Live"),_xlfn.XLOOKUP(_xlfn.TEXTJOIN(" vs ",,C10:D10),Calendar!G:G,Calendar!K:K),"") | AJ10: =IF(AND(K10<>"Match of the Day",K10<>"Match of the Day 2",K10<>"Match of the Day Repeat"),"",1+MAX(#REF!))
A11: OVN | B11: Sky Bet League One | C11: Stockport County | D11: Bolton Wanderers | E11: Live | F11: 0.5 | H11: 45872 | I11: 2025/26 | J11: Sun | K11: Whistle-to-Whistle | L11: Sky Sports Football | M11: Sky Sports | N11: 0.5 | O11: 0.53333333 | P11: 0.033333333 | Q11: 98.6 | R11: 0.16 | S11: 1.967 | T11: 120.8 | U11: 13.5 | V11: 0.186 | W11: 8.432 | X11: 15.3 | Y11: 89.3 | Z11: 0.169 | AA11: 1.836 | AB11: 111.5 | AH11: =IF(AND(B11="Premier League",E11="Live"),_xlfn.XLOOKUP(_xlfn.TEXTJOIN(" vs ",,C11:D11),Calendar!G:G,Calendar!B:B),IF(AND(B11="Premier League",E11="Highlights"),_xlfn.XLOOKUP(H11,Calendar!O:O,Calendar!N:N,,-1),"")) | AI11: =IF(AND(AH11<>"",E11="Live"),_xlfn.XLOOKUP(_xlfn.TEXTJOIN(" vs ",,C11:D11),Calendar!G:G,Calendar!K:K),"") | AJ11: =IF(AND(K11<>"Match of the Day",K11<>"Match of the Day 2",K11<>"Match of the Day Repeat"),"",1+MAX($AJ$10:AJ10))
A12: OVN | B12: Scottish Premiership | C12: Falkirk | D12: Dundee United | E12: Live | F12: 0.58333333 | H12: 45872 | I12: 2025/26 | J12: Sun | K12: Whistle-to-Whistle | L12: Sky Sports Football | M12: Sky Sports | N12: 0.58333333 | O12: 0.6625 | P12: 0.079166667 | Q12: 82.7 | R12: 0.134 | S12: 1.226 | T12: 160 | U12: 10.9 | V12: 0.15 | W12: 4.39 | X12: 19.2 | Y12: 82 | Z12: 0.156 | AA12: 1.251 | AB12: 156.8 | AH12: =IF(AND(B12="Premier League",E12="Live"),_xlfn.XLOOKUP(_xlfn.TEXTJOIN(" vs ",,C12:D12),Calendar!G:G,Calendar!B:B),IF(AND(B12="Premier League",E12="Highlights"),_xlfn.XLOOKUP(H12,Calendar!O:O,Calendar!N:N,,-1),"")) | AI12: =IF(AND(AH12<>"",E12="Live"),_xlfn.XLOOKUP(_xlfn.TEXTJOIN(" vs ",,C12:D12),Calendar!G:G,Calendar!K:K),"") | AJ12: =IF(AND(K12<>"Match of the Day",K12<>"Match of the Day 2",K12<>"Match of the Day Repeat"),"",1+MAX($AJ$10:AJ11))
A13: OVN | B13: Scottish Premiership | C13: Celtic | D13: St Mirren | E13: Live | F13: 0.6875 | H13: 45872 | I13: 2025/26 | J13: Sun | K13: Whistle-to-Whistle | L13: Sky Sports Main Event | M13: Sky Sports | N13: 0.68958333 | O13: 0.76875 | P13: 0.079166667 | Q13: 253.2 | R13: 0.41 | S13: 3.05 | T13: 394.6 | U13: 15 | V13: 0.207 | W13: 7.553 | X13: 50.1 | Y13: 249.5 | Z13: 0.473 | AA13: 3.085 | AB13: 389.1 | AH13: =IF(AND(B13="Premier League",E13="Live"),_xlfn.XLOOKUP(_xlfn.TEXTJOIN(" vs ",,C13:D13),Calendar!G:G,Calendar!B:B),IF(AND(B13="Premier League",E13="Highlights"),_xlfn.XLOOKUP(H13,Calendar!O:O,Calendar!N:N,,-1),"")) | AI13: =IF(AND(AH13<>"",E13="Live"),_xlfn.XLOOKUP(_xlfn.TEXTJOIN(" vs ",,C13:D13),Calendar!G:G,Calendar!K:K),"") | AJ13: =IF(AND(K13<>"Match of the Day",K13<>"Match of the Day 2",K13<>"Match of the Day Repeat"),"",1+MAX($AJ$10:AJ12))
A14: OVN | B14: Scottish Premiership | C14: Hearts | D14: Aberdeen | E14: Live | F14: 0.83333333 | H14: 45873 | I14: 2025/26 | J14: Mon | K14: Whistle-to-Whistle | L14: Sky Sports Main Event | M14: Sky Sports | N14: 0.83333333 | O14: 0.91319444 | P14: 0.079861111 | Q14: 192.4 | R14: 0.312 | S14: 1.811 | T14: 275.3 | U14: 6.1 | V14: 0.084 | W14: 2.796 | X14: 20.3 | Y14: 187.9 | Z14: 0.356 | AA14: 1.808 | AB14: 269.9 | AH14: =IF(AND(B14="Premier League",E14="Live"),_xlfn.XLOOKUP(_xlfn.TEXTJOIN(" vs ",,C14:D14),Calendar!G:G,Calendar!B:B),IF(AND(B14="Premier League",E14="Highlights"),_xlfn.XLOOKUP(H14,Calendar!O:O,Calendar!N:N,,-1),"")) | AI14: =IF(AND(AH14<>"",E14="Live"),_xlfn.XLOOKUP(_xlfn.TEXTJOIN(" vs ",,C14:D14),Calendar!G:G,Calendar!K:K),"") | AJ14: =IF(AND(K14<>"Match of the Day",K14<>"Match of the Day 2",K14<>"Match of the Day Repeat"),"",1+MAX($AJ$10:AJ13))
A15: OVN | B15: Carabao Cup | C15: Accrington Stanley | D15: Oldham Athletic | E15: Live | F15: 0.82291667 | H15: 45874 | I15: 2025/26 | J15: Tue | K15: Whistle-to-Whistle | L15: Sky Sports Plus | M15: Sky Sports | N15: 0.82291667 | O15: 0.90277778 | P15: 0.079861111 | Q15: 5.4 | R15: 0.009 | S15: 0.051 | T15: 17.8 | U15: 0.1 | V15: 0.001 | W15: 0.05 | X15: 2.2 | Y15: 5.3 | Z15: 0.01 | AA15: 0.051 | AB15: 17.8 | AH15: =IF(AND(B15="Premier League",E15="Live"),_xlfn.XLOOKUP(_xlfn.TEXTJOIN(" vs ",,C15:D15),Calendar!G:G,Calendar!B:B),IF(AND(B15="Premier League",E15="Highlights"),_xlfn.XLOOKUP(H15,Calendar!O:O,Calendar!N:N,,-1),"")) | AI15: =IF(AND(AH15<>"",E15="Live"),_xlfn.XLOOKUP(_xlfn.TEXTJOIN(" vs ",,C15:D15),Calendar!G:G,Calendar!K:K),"") | AJ15: =IF(AND(K15<>"Match of the Day",K15<>"Match of the Day 2",K15<>"Match of the Day Repeat"),"",1+MAX($AJ$10:AJ14))
A16: OVN | B16: UEFA Champions League | C16: Rangers | D16: Viktoria-plzen | E16: Live | F16: 0.82291667 | H16: 45874 | I16: 2025/26 | J16: Tue | K16: Whistle-to-Whistle | L16: BBC Scotland | M16: BBC | N16: 0.82291667 | O16: 0.90138889 | P16: 0.078472222 | Q16: 12.5 | R16: 0.02 | S16: 0.118 | T16: 32.4 | U16: 0 | V16: 0 | W16: 0 | X16: - | Y16: 12.5 | Z16: 0.024 | AA16: 0.121 | AB16: 32.4 | AH16: =IF(AND(B16="Premier League",E16="Live"),_xlfn.XLOOKUP(_xlfn.TEXTJOIN(" vs ",,C16:D16),Calendar!G:G,Calendar!B:B),IF(AND(B16="Premier League",E16="Highlights"),_xlfn.XLOOKUP(H16,Calendar!O:O,Calendar!N:N,,-1),"")) | AI16: =IF(AND(AH16<>"",E16="Live"),_xlfn.XLOOKUP(_xlfn.TEXTJOIN(" vs ",,C16:D16),Calendar!G:G,Calendar!K:K),"") | AJ16: =IF(AND(K16<>"Match of the Day",K16<>"Match of the Day 2",K16<>"Match of the Day Repeat"),"",1+MAX($AJ$10:AJ15))
A17: OVN | B17: Sky Bet League One | C17: Port Vale | D17: Cardiff City | E17: Live | F17: 0.83333333 | H17: 45876 | I17: 2025/26 | J17: Thu | K17: Whistle-to-Whistle | L17: Sky Sports Football | M17: Sky Sports | N17: 0.83333333 | O17: 0.91319444 | P17: 0.079861111 | Q17: 55.2 | R17: 0.089 | S17: 0.545 | T17: 88 | U17: 5.2 | V17: 0.072 | W17: 2.805 | X17: 11.7 | Y17: 50.8 | Z17: 0.096 | AA17: 0.515 | AB17: 84.2 | AH17: =IF(AND(B17="Premier League",E17="Live"),_xlfn.XLOOKUP(_xlfn.TEXTJOIN(" vs ",,C17:D17),Calendar!G:G,Calendar!B:B),IF(AND(B17="Premier League",E17="Highlights"),_xlfn.XLOOKUP(H17,Calendar!O:O,Calendar!N:N,,-1),"")) | AI17: =IF(AND(AH17<>"",E17="Live"),_xlfn.XLOOKUP(_xlfn.TEXTJOIN(" vs ",,C17:D17),Calendar!G:G,Calendar!K:K),"") | AJ17: =IF(AND(K17<>"Match of the Day",K17<>"Match of the Day 2",K17<>"Match of the Day Repeat"),"",1+MAX($AJ$10:AJ16))
A18: OVN | B18: UEFA Europa Conference League | C18: Rapid Vienna | D18: Dundee United | E18: Live | F18: 0.83333333 | H18: 45876 | I18: 2025/26 | J18: Thu | K18: Whistle-to-Whistle | L18: BBC Scotland | M18: BBC | N18: 0.83333333 | O18: 0.91666667 | P18: 0.083333333 | Q18: 171.6 | R18: 0.278 | S18: 1.7 | T18: 232.5 | U18: 8.4 | V18: 0.116 | W18: 4.506 | X18: 16.6 | Y18: 167.3 | Z18: 0.317 | AA18: 1.701 | AB18: 228.9 | AH18: =IF(AND(B18="Premier League",E18="Live"),_xlfn.XLOOKUP(_xlfn.TEXTJOIN(" vs ",,C18:D18),Calendar!G:G,Calendar!B:B),IF(AND(B18="Premier League",E18="Highlights"),_xlfn.XLOOKUP(H18,Calendar!O:O,Calendar!N:N,,-1),"")) | AI18: =IF(AND(AH18<>"",E18="Live"),_xlfn.XLOOKUP(_xlfn.TEXTJOIN(" vs ",,C18:D18),Calendar!G:G,Calendar!K:K),"") | AJ18: =IF(AND(K18<>"Match of the Day",K18<>"Match of the Day 2",K18<>"Match of the Day Repeat"),"",1+MAX($AJ$10:AJ17))
A19: OVN | B19: Sky Bet League One | C19: Port Vale | D19: Cardiff City | E19: Live | F19: 0.83333333 | H19: 45876 | I19: 2025/26 | J19: Thu | K19: Whistle-to-Whistle | L19: Sky Sports Main Event | M19: Sky Sports | N19: 0.83333333 | O19: 0.91319444 | P19: 0.079861111 | Q19: 145.1 | R19: 0.2 | S19: 1.4334 | T19: 246.8 | U19: 8.7 | V19: 0.1 | W19: 4.6925 | X19: 20.9 | Y19: 136.4 | Z19: 0.3 | AA19: 1.3835 | AB19: 240.1 | AH19: =IF(AND(B19="Premier League",E19="Live"),_xlfn.XLOOKUP(_xlfn.TEXTJOIN(" vs ",,C19:D19),Calendar!G:G,Calendar!B:B),IF(AND(B19="Premier League",E19="Highlights"),_xlfn.XLOOKUP(H19,Calendar!O:O,Calendar!N:N,,-1),"")) | AI19: =IF(AND(AH19<>"",E19="Live"),_xlfn.XLOOKUP(_xlfn.TEXTJOIN(" vs ",,C19:D19),Calendar!G:G,Calendar!K:K),"") | AJ19: =IF(AND(K19<>"Match of the Day",K19<>"Match of the Day 2",K19<>"Match of the Day Repeat"),"",1+MAX($AJ$10:AJ18))
A20: OVN | B20: Scottish Championship | C20: Ross County | D20: St Johnstone | E20: Live | F20: 0.82291667 | H20: 45877 | I20: 2025/26 | J20: Fri | K20: Whistle-to-Whistle | L20: BBC Scotland | M20: BBC | N20: 0.82430556 | O20: 0.90208333 | P20: 0.077777778 | Q20: 71.1 | R20: 0.115 | S20: 0.713 | T20: 134.2 | U20: 18.7 | V20: 0.257 | W20: 7.474 | X20: 28.6 | Y20: 69.9 | Z20: 0.133 | AA20: 0.719 | AB20: 130.6 | AH20: =IF(AND(B20="Premier League",E20="Live"),_xlfn.XLOOKUP(_xlfn.TEXTJOIN(" vs ",,C20:D20),Calendar!G:G,Calendar!B:B),IF(AND(B20="Premier League",E20="Highlights"),_xlfn.XLOOKUP(H20,Calendar!O:O,Calendar!N:N,,-1),"")) | AI20: =IF(AND(AH20<>"",E20="Live"),_xlfn.XLOOKUP(_xlfn.TEXTJOIN(" vs ",,C20:D20),Calendar!G:G,Calendar!K:K),"") | AJ20: =IF(AND(K20<>"Match of the Day",K20<>"Match of the Day 2",K20<>"Match of the Day Repeat"),"",1+MAX($AJ$10:AJ19))
A21: OVN | B21: Sky Bet Championship | C21: Birmingham City | D21: Ipswich Town | E21: Live | F21: 0.83333333 | H21: 45877 | I21: 2025/26 | J21: Fri | K21: Whistle-to-Whistle | L21: Sky Sports Main Event | M21: Sky Sports | N21: 0.83402778 | O21: 0.91597222 | P21: 0.081944444 | Q21: 517.8 | R21: 0.8 | S21: 5.2484 | T21: 690.5 | U21: 57.9 | V21: 0.8 | W21: 23.4223 | X21: 86.9 | Y21: 501 | Z21: 0.9 | AA21: 5.2007 | AB21: 669.1 | AH21: =IF(AND(B21="Premier League",E21="Live"),_xlfn.XLOOKUP(_xlfn.TEXTJOIN(" vs ",,C21:D21),Calendar!G:G,Calendar!B:B),IF(AND(B21="Premier League",E21="Highlights"),_xlfn.XLOOKUP(H21,Calendar!O:O,Calendar!N:N,,-1),"")) | AI21: =IF(AND(AH21<>"",E21="Live"),_xlfn.XLOOKUP(_xlfn.TEXTJOIN(" vs ",,C21:D21),Calendar!G:G,Calendar!K:K),"") | AJ21: =IF(AND(K21<>"Match of the Day",K21<>"Match of the Day 2",K21<>"Match of the Day Repeat"),"",1+MAX($AJ$10:AJ20))
A22: OVN | B22: Sky Bet Championship | C22: Coventry City | D22: Hull City | E22: Live | F22: 0.52083333 | H22: 45878 | I22: 2025/26 | J22: Sat | K22: Whistle-to-Whistle | L22: Sky Sports + | M22: Sky Sports | N22: 0.52152778 | O22: 0.60208333 | P22: 0.080555556 | Q22: 66.2 | R22: 0.107 | S22: 1.415 | T22: 87.4 | U22: 3 | V22: 0.041 | W22: 2.182 | X22: 3.7 | Y22: 66.2 | Z22: 0.126 | AA22: 1.464 | AB22: 87.4 | AH22: =IF(AND(B22="Premier League",E22="Live"),_xlfn.XLOOKUP(_xlfn.TEXTJOIN(" vs ",,C22:D22),Calendar!G:G,Calendar!B:B),IF(AND(B22="Premier League",E22="Highlights"),_xlfn.XLOOKUP(H22,Calendar!O:O,Calendar!N:N,,-1),"")) | AI22: =IF(AND(AH22<>"",E22="Live"),_xlfn.XLOOKUP(_xlfn.TEXTJOIN(" vs ",,C22:D22),Calendar!G:G,Calendar!K:K),"") | AJ22: =IF(AND(K22<>"Match of the Day",K22<>"Match of the Day 2",K22<>"Match of the Day Repeat"),"",1+MAX($AJ$10:AJ21))
A23: OVN | B23: Sky Bet Championship | C23: Southampton | D23: Wrexham | E23: Live | F23: 0.52083333 | H23: 45878 | I23: 2025/26 | J23: Sat | K23: Whistle-to-Whistle | L23: Sky Sports Main Event | M23: Sky Sports | N23: 0.52083333 | O23: 0.60208333 | P23: 0.08125 | Q23: 534.2 | R23: 0.865 | S23: 11.425 | T23: 736.1 | U23: 52.7 | V23: 0.725 | W23: 38.383 | X23: 78.6 | Y23: 521.8 | Z23: 0.99 | AA23: 11.548 | AB23: 715.7 | AH23: =IF(AND(B23="Premier League",E23="Live"),_xlfn.XLOOKUP(_xlfn.TEXTJOIN(" vs ",,C23:D23),Calendar!G:G,Calendar!B:B),IF(AND(B23="Premier League",E23="Highlights"),_xlfn.XLOOKUP(H23,Calendar!O:O,Calendar!N:N,,-1),"")) | AI23: =IF(AND(AH23<>"",E23="Live"),_xlfn.XLOOKUP(_xlfn.TEXTJOIN(" vs ",,C23:D23),Calendar!G:G,Calendar!K:K),"") | AJ23: =IF(AND(K23<>"Match of the Day",K23<>"Match of the Day 2",K23<>"Match of the Day Repeat"),"",1+MAX($AJ$10:AJ22))
A24: OVN | B24: Sky Bet Championship | C24: West Brom | D24: Blackburn Rovers | E24: Live | F24: 0.625 | H24: 45878 | I24: 2025/26 | J24: Sat | K24: Whistle-to-Whistle | L24: Sky Sports + | M24: Sky Sports | N24: 0.62569444 | O24: 0.70833333 | P24: 0.082638889 | Q24: 109.5 | R24: 0.177 | S24: 2.176 | T24: 157.6 | U24: 2.3 | V24: 0.032 | W24: 1.934 | X24: 2.7 | Y24: 105 | Z24: 0.199 | AA24: 2.162 | AB24: 152.4 | AH24: =IF(AND(B24="Premier League",E24="Live"),_xlfn.XLOOKUP(_xlfn.TEXTJOIN(" vs ",,C24:D24),Calendar!G:G,Calendar!B:B),IF(AND(B24="Premier League",E24="Highlights"),_xlfn.XLOOKUP(H24,Calendar!O:O,Calendar!N:N,,-1),"")) | AI24: =IF(AND(AH24<>"",E24="Live"),_xlfn.XLOOKUP(_xlfn.TEXTJOIN(" vs ",,C24:D24),Calendar!G:G,Calendar!K:K),"") | AJ24: =IF(AND(K24<>"Match of the Day",K24<>"Match of the Day 2",K24<>"Match of the Day Repeat"),"",1+MAX($AJ$10:AJ23))
A25: OVN | B25: Scottish Premiership | C25: Rangers | D25: Dundee | E25: Live | F25: 0.73958333 | H25: 45878 | I25: 2025/26 | J25: Sat | K25: Whistle-to-Whistle | L25: Premier Sports 1 | M25: Premier Sports | N25: 0.73888889 | O25: 0.81944444 | P25: 0.080555556 | Q25: 104.9 | R25: 0.17 | S25: 1.245 | T25: 131 | U25: 3.4 | V25: 0.047 | W25: 2.129 | X25: 3.5 | Y25: 104.9 | Z25: 0.199 | AA25: 1.276 | AB25: 131 | AH25: =IF(AND(B25="Premier League",E25="Live"),_xlfn.XLOOKUP(_xlfn.TEXTJOIN(" vs ",,C25:D25),Calendar!G:G,Calendar!B:B),IF(AND(B25="Premier League",E25="Highlights"),_xlfn.XLOOKUP(H25,Calendar!O:O,Calendar!N:N,,-1),"")) | AI25: =IF(AND(AH25<>"",E25="Live"),_xlfn.XLOOKUP(_xlfn.TEXTJOIN(" vs ",,C25:D25),Calendar!G:G,Calendar!K:K),"") | AJ25: =IF(AND(K25<>"Match of the Day",K25<>"Match of the Day 2",K25<>"Match of the Day Repeat"),"",1+MAX($AJ$10:AJ24))
A26: OVN | B26: Sky Bet Championship | C26: Sheffield United | D26: Bristol City | E26: Live | F26: 0.72916667 | H26: 45878 | I26: 2025/26 | J26: Sat | K26: Whistle-to-Whistle | L26: Sky Sports Main Event | M26: Sky Sports | N26: 0.72916667 | O26: 0.80833333 | P26: 0.079166667 | Q26: 308.3 | R26: 0.5 | S26: 3.7927 | T26: 428.5 | U26: 25.4 | V26: 0.3 | W26: 15.4878 | X26: 57 | Y26: 301.1 | Z26: 0.5 | AA26: 3.7946 | AB26: 423.9 | AH26: =IF(AND(B26="Premier League",E26="Live"),_xlfn.XLOOKUP(_xlfn.TEXTJOIN(" vs ",,C26:D26),Calendar!G:G,Calendar!B:B),IF(AND(B26="Premier League",E26="Highlights"),_xlfn.XLOOKUP(H26,Calendar!O:O,Calendar!N:N,,-1),"")) | AI26: =IF(AND(AH26<>"",E26="Live"),_xlfn.XLOOKUP(_xlfn.TEXTJOIN(" vs ",,C26:D26),Calendar!G:G,Calendar!K:K),"") | AJ26: =IF(AND(K26<>"Match of the Day",K26<>"Match of the Day 2",K26<>"Match of the Day Repeat"),"",1+MAX($AJ$10:AJ25))
A27: OVN | B27: Scottish Premiership | C27: Aberdeen | D27: Celtic | E27: Live | F27: 0.52083333 | H27: 45879 | I27: 2025/26 | J27: Sun | K27: Whistle-to-Whistle | L27: Sky Sports Football | M27: Sky Sports | N27: 0.52152778 | O27: 0.59930556 | P27: 0.077777778 | Q27: 99.3 | R27: 0.161 | S27: 2.26 | T27: 142.5 | U27: 5.9 | V27: 0.081 | W27: 4.66 | X27: 11 | Y27: 91.2 | Z27: 0.173 | AA27: 2.154 | AB27: 119.8 | AH27: =IF(AND(B27="Premier League",E27="Live"),_xlfn.XLOOKUP(_xlfn.TEXTJOIN(" vs ",,C27:D27),Calendar!G:G,Calendar!B:B),IF(AND(B27="Premier League",E27="Highlights"),_xlfn.XLOOKUP(H27,Calendar!O:O,Calendar!N:N,,-1),"")) | AI27: =IF(AND(AH27<>"",E27="Live"),_xlfn.XLOOKUP(_xlfn.TEXTJOIN(" vs ",,C27:D27),Calendar!G:G,Calendar!K:K),"") | AJ27: =IF(AND(K27<>"Match of the Day",K27<>"Match of the Day 2",K27<>"Match of the Day Repeat"),"",1+MAX($AJ$10:AJ26))
A28: OVN | B28: FA Community Shield | C28: Liverpool | D28: Crystal Palace | E28: Live | F28: 0.625 | H28: 45879 | I28: 2025/26 | J28: Sun | K28: Whistle-to-Whistle | L28: TNT Sports 1 | M28: TNT Sports | N28: 0.62638889 | O28: 0.71944444 | P28: 0.093055556 | Q28: 1289 | R28: 2.087 | S28: 19.814 | T28: 1715.1 | U28: 216.7 | V28: 2.981 | W28: 60.228 | X28: 278.1 | Y28: 1215.8 | Z28: 2.307 | AA28: 19.426 | AB28: 1607.1 | AH28: =IF(AND(B28="Premier League",E28="Live"),_xlfn.XLOOKUP(_xlfn.TEXTJOIN(" vs ",,C28:D28),Calendar!G:G,Calendar!B:B),IF(AND(B28="Premier League",E28="Highlights"),_xlfn.XLOOKUP(H28,Calendar!O:O,Calendar!N:N,,-1),"")) | AI28: =IF(AND(AH28<>"",E28="Live"),_xlfn.XLOOKUP(_xlfn.TEXTJOIN(" vs ",,C28:D28),Calendar!G:G,Calendar!K:K),"") | AJ28: =IF(AND(K28<>"Match of the Day",K28<>"Match of the Day 2",K28<>"Match of the Day Repeat"),"",1+MAX($AJ$10:AJ27))
A29: OVN | B29: Sky Bet Championship | C29: Leicester City | D29: Sheffield Wednesday | E29: Live | F29: 0.6875 | H29: 45879 | I29: 2025/26 | J29: Sun | K29: Whistle-to-Whistle | L29: Sky Sports Main Event | M29: Sky Sports | N29: 0.6875 | O29: 0.77013889 | P29: 0.082638889 | Q29: 539.4 | R29: 0.8 | S29: 6.9666 | T29: 728.1 | U29: 57 | V29: 0.8 | W29: 17.3993 | X29: 110.8 | Y29: 514.7 | Z29: 1 | AA29: 6.8681 | AB29: 692.6 | AH29: =IF(AND(B29="Premier League",E29="Live"),_xlfn.XLOOKUP(_xlfn.TEXTJOIN(" vs ",,C29:D29),Calendar!G:G,Calendar!B:B),IF(AND(B29="Premier League",E29="Highlights"),_xlfn.XLOOKUP(H29,Calendar!O:O,Calendar!N:N,,-1),"")) | AI29: =IF(AND(AH29<>"",E29="Live"),_xlfn.XLOOKUP(_xlfn.TEXTJOIN(" vs ",,C29:D29),Calendar!G:G,Calendar!K:K),"") | AJ29: =IF(AND(K29<>"Match of the Day",K29<>"Match of the Day 2",K29<>"Match of the Day Repeat"),"",1+MAX($AJ$10:AJ28))
A30: OVN | B30: Carabao Cup | C30: West Brom | D30: Derby County | E30: Live | F30: 0.82291667 | H30: 45881 | I30: 2025/26 | J30: Tue | K30: Whistle-to-Whistle | L30: Sky Sports + | M30: Sky Sports | N30: 0.82361111 | O30: 0.9125 | P30: 0.088888889 | AH30: =IF(AND(B30="Premier League",E30="Live"),_xlfn.XLOOKUP(_xlfn.TEXTJOIN(" vs ",,C30:D30),Calendar!G:G,Calendar!B:B),IF(AND(B30="Premier League",E30="Highlights"),_xlfn.XLOOKUP(H30,Calendar!O:O,Calendar!N:N,,-1),"")) | AI30: =IF(AND(AH30<>"",E30="Live"),_xlfn.XLOOKUP(_xlfn.TEXTJOIN(" vs ",,C30:D30),Calendar!G:G,Calendar!K:K),"") | AJ30: =IF(AND(K30<>"Match of the Day",K30<>"Match of the Day 2",K30<>"Match of the Day Repeat"),"",1+MAX($AJ$10:AJ29))
A31: OVN | B31: Carabao Cup | C31: Bromley | D31: Ipswich Town | E31: Live | F31: 0.83333333 | H31: 45881 | I31: 2025/26 | J31: Tue | K31: Whistle-to-Whistle | L31: Sky Sports Football | M31: Sky Sports | N31: 0.83333333 | O31: 0.91944444 | P31: 0.086111111 | Q31: 31.5 | R31: 0.051 | S31: 0.316 | T31: 73.2 | U31: 4.3 | V31: 0.059 | W31: 2.57 | X31: 16.5 | Y31: 30.5 | Z31: 0.058 | AA31: 0.313 | AB31: 69.4 | AH31: =IF(AND(B31="Premier League",E31="Live"),_xlfn.XLOOKUP(_xlfn.TEXTJOIN(" vs ",,C31:D31),Calendar!G:G,Calendar!B:B),IF(AND(B31="Premier League",E31="Highlights"),_xlfn.XLOOKUP(H31,Calendar!O:O,Calendar!N:N,,-1),"")) | AI31: =IF(AND(AH31<>"",E31="Live"),_xlfn.XLOOKUP(_xlfn.TEXTJOIN(" vs ",,C31:D31),Calendar!G:G,Calendar!K:K),"") | AJ31: =IF(AND(K31<>"Match of the Day",K31<>"Match of the Day 2",K31<>"Match of the Day Repeat"),"",1+MAX($AJ$10:AJ30))
A32: OVN | B32: Carabao Cup | C32: Huddersfield Town | D32: Leicester City | E32: Live | F32: 0.82291667 | H32: 45882 | I32: 2025/26 | J32: Wed | K32: Whistle-to-Whistle | L32: Sky Sports + | M32: Sky Sports | N32: 0.82291667 | O32: 0.91041667 | P32: 0.0875 | Q32: 95.8 | R32: 0.155 | S32: 0.904 | T32: 143.6 | U32: 4.2 | V32: 0.058 | W32: 1.513 | X32: 11.7 | Y32: 88.1 | Z32: 0.167 | AA32: 0.85 | AB32: 129.6 | AH32: =IF(AND(B32="Premier League",E32="Live"),_xlfn.XLOOKUP(_xlfn.TEXTJOIN(" vs ",,C32:D32),Calendar!G:G,Calendar!B:B),IF(AND(B32="Premier League",E32="Highlights"),_xlfn.XLOOKUP(H32,Calendar!O:O,Calendar!N:N,,-1),"")) | AI32: =IF(AND(AH32<>"",E32="Live"),_xlfn.XLOOKUP(_xlfn.TEXTJOIN(" vs ",,C32:D32),Calendar!G:G,Calendar!K:K),"") | AJ32: =IF(AND(K32<>"Match of the Day",K32<>"Match of the Day 2",K32<>"Match of the Day Repeat"),"",1+MAX($AJ$10:AJ31))
A33: OVN | B33: Carabao Cup | C33: Birmingham City | D33: Sheffield United | E33: Live | F33: 0.83333333 | H33: 45882 | I33: 2025/26 | J33: Wed | K33: Whistle-to-Whistle | L33: ITV 4 | M33: ITV | N33: 0.83333333 | O33: 0.91319444 | P33: 0.079861111 | Q33: 373.1 | R33: 0.604 | S33: 3.521 | T33: 481.3 | U33: 8 | V33: 0.11 | W33: 2.828 | X33: 40 | Y33: 362.3 | Z33: 0.687 | AA33: 3.496 | AB33: 472.7 | AH33: =IF(AND(B33="Premier League",E33="Live"),_xlfn.XLOOKUP(_xlfn.TEXTJOIN(" vs ",,C33:D33),Calendar!G:G,Calendar!B:B),IF(AND(B33="Premier League",E33="Highlights"),_xlfn.XLOOKUP(H33,Calendar!O:O,Calendar!N:N,,-1),"")) | AI33: =IF(AND(AH33<>"",E33="Live"),_xlfn.XLOOKUP(_xlfn.TEXTJOIN(" vs ",,C33:D33),Calendar!G:G,Calendar!K:K),"") | AJ33: =IF(AND(K33<>"Match of the Day",K33<>"Match of the Day 2",K33<>"Match of the Day Repeat"),"",1+MAX($AJ$10:AJ32))
A34: OVN | B34: UEFA Super Cup | C34: PSG | D34: Tottenham Hotspur | E34: Live | F34: 0.83333333 | H34: 45882 | I34: 2025/26 | J34: Wed | K34: Whistle-to-Whistle | L34: TNT Sports 1 | M34: TNT Sports | N34: 0.83472222 | O34: 0.92361111 | P34: 0.088888889 | Q34: 786.3 | R34: 1.273 | S34: 7.512 | T34: 1060.3 | U34: 133.5 | V34: 1.837 | W34: 47.24 | X34: 176.2 | Y34: 754.1 | Z34: 1.431 | AA34: 7.366 | AB34: 1021.3 | AH34: =IF(AND(B34="Premier League",E34="Live"),_xlfn.XLOOKUP(_xlfn.TEXTJOIN(" vs ",,C34:D34),Calendar!G:G,Calendar!B:B),IF(AND(B34="Premier League",E34="Highlights"),_xlfn.XLOOKUP(H34,Calendar!O:O,Calendar!N:N,,-1),"")) | AI34: =IF(AND(AH34<>"",E34="Live"),_xlfn.XLOOKUP(_xlfn.TEXTJOIN(" vs ",,C34:D34),Calendar!G:G,Calendar!K:K),"") | AJ34: =IF(AND(K34<>"Match of the Day",K34<>"Match of the Day 2",K34<>"Match of the Day Repeat"),"",1+MAX($AJ$10:AJ33))
A35: OVN | B35: Carabao Cup | E35: Highlights | F35: 0.8125 | G35: - | H35: 45882 | I35: 2025/26 | J35: Wed | K35: Carabao Cup Highlights | L35: ITV 4 | M35: ITV | N35: 0.375 | O35: 0.43748843 | P35: 0.0625 | Q35: 60.4 | R35: 0.098 | S35: 1.625 | T35: 102.9 | U35: 2.2 | V35: 0.03 | W35: 2.138 | X35: 16.5 | Y35: 58.8 | Z35: 0.112 | AA35: 1.652 | AB35: 99.3 | AH35: =IF(AND(B35="Premier League",E35="Live"),_xlfn.XLOOKUP(_xlfn.TEXTJOIN(" vs ",,C35:D35),Calendar!G:G,Calendar!B:B),IF(AND(B35="Premier League",E35="Highlights"),_xlfn.XLOOKUP(H35,Calendar!O:O,Calendar!N:N,,-1),"")) | AI35: =IF(AND(AH35<>"",E35="Live"),_xlfn.XLOOKUP(_xlfn.TEXTJOIN(" vs ",,C35:D35),Calendar!G:G,Calendar!K:K),"") | AJ35: =IF(AND(K35<>"Match of the Day",K35<>"Match of the Day 2",K35<>"Match of the Day Repeat"),"",1+MAX($AJ$10:AJ34))
A36: OVN | B36: UEFA Europa Conference League | C36: Hibernian | D36: Partizan Belgrade | E36: Live | F36: 0.83333333 | H36: 45883 | I36: 2025/26 | J36: Thu | K36: Whistle-to-Whistle | L36: BBC Scotland | M36: BBC | N36: 0.83472222 | O36: 0.94236111 | P36: 0.10763889 | Q36: 230.7 | R36: 0.374 | S36: 2.4443 | T36: 318.9 | U36: 8.6 | V36: 0.118 | W36: 5.0618 | X36: 39.4 | Y36: 224.1 | Z36: 0.425 | AA36: 2.4268 | AB36: 312.1 | AH36: =IF(AND(B36="Premier League",E36="Live"),_xlfn.XLOOKUP(_xlfn.TEXTJOIN(" vs ",,C36:D36),Calendar!G:G,Calendar!B:B),IF(AND(B36="Premier League",E36="Highlights"),_xlfn.XLOOKUP(H36,Calendar!O:O,Calendar!N:N,,-1),"")) | AI36: =IF(AND(AH36<>"",E36="Live"),_xlfn.XLOOKUP(_xlfn.TEXTJOIN(" vs ",,C36:D36),Calendar!G:G,Calendar!K:K),"") | AJ36: =IF(AND(K36<>"Match of the Day",K36<>"Match of the Day 2",K36<>"Match of the Day Repeat"),"",1+MAX($AJ$10:AJ35))
A37: OVN | B37: Scottish League Cup | C37: Celtic | D37: Falkirk | E37: Live | F37: 0.82291667 | H37: 45884 | I37: 2025/26 | J37: Fri | K37: Whistle-to-Whistle | L37: Premier Sports 1 | M37: Premier Sports | N37: 0.82361111 | O37: 0.90138889 | P37: 0.077777778 | Q37: 42.6 | R37: 0.069 | S37: 0.4018 | T37: 73.2 | U37: 0.4 | V37: 0.006 | W37: 0.0847 | X37: 5.3 | Y37: 41.4 | Z37: 0.079 | AA37: 0.4021 | AB37: 70.9 | AH37: =IF(AND(B37="Premier League",E37="Live"),_xlfn.XLOOKUP(_xlfn.TEXTJOIN(" vs ",,C37:D37),Calendar!G:G,Calendar!B:B),IF(AND(B37="Premier League",E37="Highlights"),_xlfn.XLOOKUP(H37,Calendar!O:O,Calendar!N:N,,-1),"")) | AI37: =IF(AND(AH37<>"",E37="Live"),_xlfn.XLOOKUP(_xlfn.TEXTJOIN(" vs ",,C37:D37),Calendar!G:G,Calendar!K:K),"") | AJ37: =IF(AND(K37<>"Match of the Day",K37<>"Match of the Day 2",K37<>"Match of the Day Repeat"),"",1+MAX($AJ$10:AJ36))
A38: OVN | B38: Premier League | C38: Liverpool | D38: AFC Bournemouth | E38: Live | F38: 0.83333333 | H38: 45884 | I38: 2025/26 | J38: Fri | K38: Whistle-to-Whistle | L38: Sky Sports Main Event | M38: Sky Sports | N38: 0.83402778 | O38: 0.91388889 | P38: 0.079861111 | Q38: 2022.8 | R38: 3.2 | S38: 19.1 | T38: 2425.8 | U38: 336.1 | V38: 4.7 | W38: 68.7 | X38: 424.7 | Y38: 1873.8 | Z38: 3.5 | AA38: 18.2 | AB38: 2229.7 | AH38: =IF(AND(B38="Premier League",E38="Live"),_xlfn.XLOOKUP(_xlfn.TEXTJOIN(" vs ",,C38:D38),Calendar!G:G,Calendar!B:B),IF(AND(B38="Premier League",E38="Highlights"),_xlfn.XLOOKUP(H38,Calendar!O:O,Calendar!N:N,,-1),"")) -> #N/A | AI38: =IF(AND(AH38<>"",E38="Live"),_xlfn.XLOOKUP(_xlfn.TEXTJOIN(" vs ",,C38:D38),Calendar!G:G,Calendar!K:K),"") -> #N/A | AJ38: =IF(AND(K38<>"Match of the Day",K38<>"Match of the Day 2",K38<>"Match of the Day Repeat"),"",1+MAX($AJ$10:AJ37))
A39: OVN | B39: Sky Bet Championship | C39: Derby County | D39: Coventry City | E39: Live | F39: 0.52083333 | H39: 45885 | I39: 2025/26 | J39: Sat | K39: Whistle-to-Whistle | L39: Sky Sports+ | M39: Sky Sports | N39: 0.52083333 | O39: 0.60625 | P39: 0.085416667 | Q39: 103 | R39: 0.167 | S39: 1.8697 | T39: 224.2 | U39: 11.2 | V39: 0.154 | W39: 3.8382 | X39: 36.9 | Y39: 79.2 | Z39: 0.15 | AA39: 1.5003 | AB39: 190.1 | AH39: =IF(AND(B39="Premier League",E39="Live"),_xlfn.XLOOKUP(_xlfn.TEXTJOIN(" vs ",,C39:D39),Calendar!G:G,Calendar!B:B),IF(AND(B39="Premier League",E39="Highlights"),_xlfn.XLOOKUP(H39,Calendar!O:O,Calendar!N:N,,-1),"")) | AI39: =IF(AND(AH39<>"",E39="Live"),_xlfn.XLOOKUP(_xlfn.TEXTJOIN(" vs ",,C39:D39),Calendar!G:G,Calendar!K:K),"") | AJ39: =IF(AND(K39<>"Match of the Day",K39<>"Match of the Day 2",K39<>"Match of the Day Repeat"),"",1+MAX($AJ$10:AJ38))
A40: OVN | B40: Sky Bet Championship | C40: Wrexham | D40: West Brom | E40: Live | F40: 0.52083333 | H40: 45885 | I40: 2025/26 | J40: Sat | K40: Whistle-to-Whistle | L40: ITV1 | M40: ITV | N40: 0.52083333 | O40: 0.6 | P40: 0.079166667 | Q40: 564.2 | R40: 0.9 | S40: 10.2 | T40: 695.3 | U40: 18.6 | V40: 0.3 | W40: 6.3 | X40: 30.3 | Y40: 531.3 | Z40: 1 | AA40: 10 | AB40: 650.1 | AH40: =IF(AND(B40="Premier League",E40="Live"),_xlfn.XLOOKUP(_xlfn.TEXTJOIN(" vs ",,C40:D40),Calendar!G:G,Calendar!B:B),IF(AND(B40="Premier League",E40="Highlights"),_xlfn.XLOOKUP(H40,Calendar!O:O,Calendar!N:N,,-1),"")) | AI40: =IF(AND(AH40<>"",E40="Live"),_xlfn.XLOOKUP(_xlfn.TEXTJOIN(" vs ",,C40:D40),Calendar!G:G,Calendar!K:K),"") | AJ40: =IF(AND(K40<>"Match of the Day",K40<>"Match of the Day 2",K40<>"Match of the Day Repeat"),"",1+MAX($AJ$10:AJ39))
...

Sheet Sheet1

Sheet CDT Audiences
A1: x
A2: x
A3: x
A4: x
A5: x
A6: x
A7: x
A8: x | Q8: All Individuals 4+ (1 Minute) | U8: Men 16-34 (1 Minute) | Y8: Adults 16+ (1 Minute)
A9: Type | B9: Competition | C9: Home Team | D9: Away Team | E9: Type of programme | F9: Time slot | G9: TV Package | H9: Date | I9: Season | J9: Day | K9: Programme Title | L9: Channel | M9: Broadcaster | N9: Start Time | O9: End Time | P9: Duration | Q9: 000's | R9: TVR | S9: Share | T9: Peak | U9: 000's | V9: TVR | W9: Share | X9: Peak | Y9: 000's | Z9: TVR | AA9: Share | AB9: Peak | AC9: OTT Total Audience | AD9: PC/Laptop | AE9: Tablet | AF9: Smart Phone | AG9: Match Type | AH9: Matchweek
A10: CDT | B10: Scottish Premiership | C10: Motherwell | D10: Rangers | E10: Live | F10: 0.72916667 | H10: 45871 | I10: 2025/26 | J10: Sat | K10: Whistle-to-Whistle | L10: Sky Sports Main Event | M10: Sky Sports | N10: 0.72916667 | O10: 0.80694444 | P10: 0.077777778 | Q10: 173.4 | R10: 0.281 | S10: 2.005 | T10: 244.4 | U10: 13.9 | V10: 0.191 | W10: 6.186 | X10: 40.2 | Y10: 171.5 | Z10: 0.325 | AA10: 2.062 | AB10: 238.9 | AH10: =IF(AND(B10="Premier League",E10="Live"),_xlfn.XLOOKUP(_xlfn.TEXTJOIN(" vs ",,C10:D10),Calendar!G:G,Calendar!B:B),IF(AND(B10="Premier League",E10="Highlights"),_xlfn.XLOOKUP(H10,Calendar!O:O,Calendar!N:N,,-1),""))
A11: CDT | B11: Scottish Premiership | C11: Motherwell | D11: Rangers | E11: Live | F11: 0.72916667 | H11: 45871 | I11: 2025/26 | J11: Sat | K11: Whistle-to-Whistle | L11: Sky Sports Football | M11: Sky Sports | N11: 0.72916667 | O11: 0.80694444 | P11: 0.077777778 | Q11: 97.6 | R11: 0.158 | S11: 1.129 | T11: 136.7 | U11: 14.2 | V11: 0.195 | W11: 6.32 | X11: 23.7 | Y11: 96 | Z11: 0.182 | AA11: 1.154 | AB11: 134.9 | AH11: =IF(AND(B11="Premier League",E11="Live"),_xlfn.XLOOKUP(_xlfn.TEXTJOIN(" vs ",,C11:D11),Calendar!G:G,Calendar!B:B),IF(AND(B11="Premier League",E11="Highlights"),_xlfn.XLOOKUP(H11,Calendar!O:O,Calendar!N:N,,-1),""))
A12: CDT | B12: Sky Bet League One | C12: Stockport County | D12: Bolton Wanderers | E12: Live | F12: 0.5 | H12: 45872 | I12: 2025/26 | J12: Sun | K12: Whistle-to-Whistle | L12: Sky Sports Football | M12: Sky Sports | N12: 0.5 | O12: 0.53333333 | P12: 0.033333333 | Q12: 98.6 | R12: 0.16 | S12: 1.905 | T12: 120.8 | U12: 13.5 | V12: 0.186 | W12: 8.113 | X12: 15.3 | Y12: 89.3 | Z12: 0.169 | AA12: 1.778 | AB12: 111.5 | AH12: =IF(AND(B12="Premier League",E12="Live"),_xlfn.XLOOKUP(_xlfn.TEXTJOIN(" vs ",,C12:D12),Calendar!G:G,Calendar!B:B),IF(AND(B12="Premier League",E12="Highlights"),_xlfn.XLOOKUP(H12,Calendar!O:O,Calendar!N:N,,-1),""))
A13: CDT | B13: Scottish Premiership | C13: Falkirk | D13: Dundee United | E13: Live | F13: 0.58333333 | H13: 45872 | I13: 2025/26 | J13: Sun | K13: Whistle-to-Whistle | L13: Sky Sports Football | M13: Sky Sports | N13: 0.58333333 | O13: 0.6625 | P13: 0.079166667 | Q13: 82.7 | R13: 0.134 | S13: 1.185 | T13: 160 | U13: 10.9 | V13: 0.15 | W13: 4.115 | X13: 19.2 | Y13: 82 | Z13: 0.156 | AA13: 1.213 | AB13: 156.8 | AH13: =IF(AND(B13="Premier League",E13="Live"),_xlfn.XLOOKUP(_xlfn.TEXTJOIN(" vs ",,C13:D13),Calendar!G:G,Calendar!B:B),IF(AND(B13="Premier League",E13="Highlights"),_xlfn.XLOOKUP(H13,Calendar!O:O,Calendar!N:N,,-1),""))
A14: CDT | B14: Scottish Premiership | C14: Celtic | D14: St Mirren | E14: Live | F14: 0.6875 | H14: 45872 | I14: 2025/26 | J14: Sun | K14: Whistle-to-Whistle | L14: Sky Sports Main Event | M14: Sky Sports | N14: 0.68958333 | O14: 0.76875 | P14: 0.079166667 | Q14: 115.3 | R14: 0.187 | S14: 1.327 | T14: 193 | U14: 13.2 | V14: 0.182 | W14: 6.134 | X14: 23.8 | Y14: 113 | Z14: 0.214 | AA14: 1.338 | AB14: 187.5 | AH14: =IF(AND(B14="Premier League",E14="Live"),_xlfn.XLOOKUP(_xlfn.TEXTJOIN(" vs ",,C14:D14),Calendar!G:G,Calendar!B:B),IF(AND(B14="Premier League",E14="Highlights"),_xlfn.XLOOKUP(H14,Calendar!O:O,Calendar!N:N,,-1),""))
A15: CDT | B15: Scottish Premiership | C15: Celtic | D15: St Mirren | E15: Live | F15: 0.6875 | H15: 45872 | I15: 2025/26 | J15: Sun | K15: Whistle-to-Whistle | L15: Sky Sports Football | M15: Sky Sports | N15: 0.68958333 | O15: 0.76875 | P15: 0.079166667 | Q15: 138 | R15: 0.223 | S15: 1.588 | T15: 201.6 | U15: 1.8 | V15: 0.025 | W15: 0.836 | X15: 26.3 | Y15: 136.5 | Z15: 0.259 | AA15: 1.616 | AB15: 201.6 | AH15: =IF(AND(B15="Premier League",E15="Live"),_xlfn.XLOOKUP(_xlfn.TEXTJOIN(" vs ",,C15:D15),Calendar!G:G,Calendar!B:B),IF(AND(B15="Premier League",E15="Highlights"),_xlfn.XLOOKUP(H15,Calendar!O:O,Calendar!N:N,,-1),""))
A16: CDT | B16: Scottish Premiership | C16: Hearts | D16: Aberdeen | E16: Live | F16: 0.83333333 | H16: 45873 | I16: 2025/26 | J16: Mon | K16: Whistle-to-Whistle | L16: Sky Sports Main Event | M16: Sky Sports | N16: 0.83333333 | O16: 0.91319444 | P16: 0.079861111 | Q16: 102 | R16: 0.165 | S16: 0.788 | T16: 159.9 | U16: 6 | V16: 0.083 | W16: 2.021 | X16: 17.5 | Y16: 98.8 | Z16: 0.187 | AA16: 0.779 | AB16: 157.8 | AH16: =IF(AND(B16="Premier League",E16="Live"),_xlfn.XLOOKUP(_xlfn.TEXTJOIN(" vs ",,C16:D16),Calendar!G:G,Calendar!B:B),IF(AND(B16="Premier League",E16="Highlights"),_xlfn.XLOOKUP(H16,Calendar!O:O,Calendar!N:N,,-1),""))
A17: CDT | B17: Scottish Premiership | C17: Hearts | D17: Aberdeen | E17: Live | F17: 0.83333333 | H17: 45873 | I17: 2025/26 | J17: Mon | K17: Whistle-to-Whistle | L17: Sky Sports Football | M17: Sky Sports | N17: 0.83333333 | O17: 0.91319444 | P17: 0.079861111 | Q17: 90.5 | R17: 0.147 | S17: 0.699 | T17: 115.4 | U17: 0.1 | V17: 0.001 | W17: 0.034 | X17: 2.8 | Y17: 89.1 | Z17: 0.169 | AA17: 0.703 | AB17: 112.1 | AH17: =IF(AND(B17="Premier League",E17="Live"),_xlfn.XLOOKUP(_xlfn.TEXTJOIN(" vs ",,C17:D17),Calendar!G:G,Calendar!B:B),IF(AND(B17="Premier League",E17="Highlights"),_xlfn.XLOOKUP(H17,Calendar!O:O,Calendar!N:N,,-1),""))
A18: CDT | B18: Carabao Cup | C18: Accrington Stanley | D18: Oldham Athletic | E18: Live | F18: 0.82291667 | H18: 45874 | I18: 2025/26 | J18: Tue | K18: Whistle-to-Whistle | L18: Sky Sports Plus | M18: Sky Sports | N18: 0.82291667 | O18: 0.90277778 | P18: 0.079861111 | Q18: 50.2 | R18: 0.081 | S18: 0.435 | T18: 99.3 | U18: 7.6 | V18: 0.105 | W18: 2.889 | X18: 24.5 | Y18: 50 | Z18: 0.095 | AA18: 0.445 | AB18: 99.3 | AH18: =IF(AND(B18="Premier League",E18="Live"),_xlfn.XLOOKUP(_xlfn.TEXTJOIN(" vs ",,C18:D18),Calendar!G:G,Calendar!B:B),IF(AND(B18="Premier League",E18="Highlights"),_xlfn.XLOOKUP(H18,Calendar!O:O,Calendar!N:N,,-1),""))
A19: CDT | B19: UEFA Champions League | C19: Rangers | D19: Viktoria-plzen | E19: Live | F19: 0.82291667 | H19: 45874 | I19: 2025/26 | J19: Tue | K19: Whistle-to-Whistle | L19: BBC Scotland | M19: BBC | N19: 0.82291667 | O19: 0.90138889 | P19: 0.078472222 | Q19: 331.9 | R19: 0.537 | S19: 2.879 | T19: 389.1 | U19: 14.3 | V19: 0.197 | W19: 5.435 | X19: 20.9 | Y19: 305.2 | Z19: 0.579 | AA19: 2.722 | AB19: 363.9 | AH19: =IF(AND(B19="Premier League",E19="Live"),_xlfn.XLOOKUP(_xlfn.TEXTJOIN(" vs ",,C19:D19),Calendar!G:G,Calendar!B:B),IF(AND(B19="Premier League",E19="Highlights"),_xlfn.XLOOKUP(H19,Calendar!O:O,Calendar!N:N,,-1),""))
A20: CDT | B20: Sky Bet League One | C20: Port Vale | D20: Cardiff City | E20: Live | F20: 0.83333333 | H20: 45876 | I20: 2025/26 | J20: Thu | K20: Whistle-to-Whistle | L20: Sky Sports Football | M20: Sky Sports | N20: 0.83333333 | O20: 0.91319444 | P20: 0.079861111 | Q20: 55.2 | R20: 0.1 | S20: 0.5453 | T20: 88 | U20: 5.2 | V20: 0.1 | W20: 2.8047 | X20: 11.7 | Y20: 50.8 | Z20: 0.1 | AA20: 0.5153 | AB20: 84.2 | AH20: =IF(AND(B20="Premier League",E20="Live"),_xlfn.XLOOKUP(_xlfn.TEXTJOIN(" vs ",,C20:D20),Calendar!G:G,Calendar!B:B),IF(AND(B20="Premier League",E20="Highlights"),_xlfn.XLOOKUP(H20,Calendar!O:O,Calendar!N:N,,-1),""))
A21: CDT | B21: UEFA Europa Conference League | C21: Rapid Vienna | D21: Dundee United | E21: Live | F21: 0.83333333 | H21: 45876 | I21: 2025/26 | J21: Thu | K21: Whistle-to-Whistle | L21: BBC Scotland | M21: BBC | N21: 0.83333333 | O21: 0.91666667 | P21: 0.083333333 | Q21: 171.6 | R21: 0.3 | S21: 1.6997 | T21: 232.5 | U21: 8.4 | V21: 0.1 | W21: 4.5064 | X21: 16.6 | Y21: 167.3 | Z21: 0.3 | AA21: 1.7013 | AB21: 228.9 | AH21: =IF(AND(B21="Premier League",E21="Live"),_xlfn.XLOOKUP(_xlfn.TEXTJOIN(" vs ",,C21:D21),Calendar!G:G,Calendar!B:B),IF(AND(B21="Premier League",E21="Highlights"),_xlfn.XLOOKUP(H21,Calendar!O:O,Calendar!N:N,,-1),""))
... A53: CDT | B53: Premier League | C53: Wolverhampton Wanderers | D53: Manchester City | E53: Live | F53: 0.72916667 | H53: 45885 | I53: 2025/26 | J53: Sat | K53: Whistle-to-Whistle | L53: Sky Sports Premier League | M53: Sky Sports | N53: 0.72916667 | O53: 0.8125 | P53: 0.083333333 | Q53: 475.2 | R53: 0.77 | S53: 5.2799 | T53: 624.9 | U53: 76.5 | V53: 1.052 | W53: 21.8571 | X53: 116.2 | Y53: 443.2 | Z53: 0.841 | AA53: 5.0687 | AB53: 569.5 | AH53: =IF(AND(B53="Premier League",E53="Live"),_xlfn.XLOOKUP(_xlfn.TEXTJOIN(" vs ",,C53:D53),Calendar!G:G,Calendar!B:B),IF(AND(B53="Premier League",E53="Highlights"),_xlfn.XLOOKUP(H53,Calendar!O:O,Calendar!N:N,,-1),"")) -> #N/A
A54: CDT | B54: Scottish League Cup | C54: Rangers | D54: Alloa Athletic | E54: Live | F54: 0.73958333 | H54: 45885 | I54: 2025/26 | J54: Sat | K54: Whistle-to-Whistle | L54: Premier Sports 1 | M54: Premier Sports | N54: 0.74027778 | O54: 0.81666667 | P54: 0.076388889 | Q54: 46 | R54: 0.074 | S54: 0.4999 | T54: 65.3 | U54: 0 | V54: 0 | W54: 0 | X54: - | Y54: 44.7 | Z54: 0.085 | AA54: 0.5004 | AB54: 61.2 | AH54: =IF(AND(B54="Premier League",E54="Live"),_xlfn.XLOOKUP(_xlfn.TEXTJOIN(" vs ",,C54:D54),Calendar!G:G,Calendar!B:B),IF(AND(B54="Premier League",E54="Highlights"),_xlfn.XLOOKUP(H54,Calendar!O:O,Calendar!N:N,,-1),""))
A55: CDT | B55: Premier League | C55: Tottenham Hotspur | D55: Burnley | E55: Near Live | F55: 0.85416667 | H55: 45885 | I55: 2024/25 | J55: Sat | K55: Whistle-to-Whistle | L55: Sky Sports Premier League | M55: Sky Sports | N55: 0.86111111 | O55: 0.93402778 | P55: 0.072916667 | Q55: 63.4 | R55: 0.103 | S55: 0.6123 | T55: 117.5 | U55: 0 | V55: 0 | W55: 0 | X55: - | Y55: 63.1 | Z55: 0.12 | AA55: 0.6229 | AB55: 111.8 | AH55: =IF(AND(B55="Premier League",E55="Live"),_xlfn.XLOOKUP(_xlfn.TEXTJOIN(" vs ",,C55:D55),Calendar!G:G,Calendar!B:B),IF(AND(B55="Premier League",E55="Highlights"),_xlfn.XLOOKUP(H55,Calendar!O:O,Calendar!N:N,,-1),""))
A56: CDT | B56: Premier League | E56: Highlights | F56: 0.9375 | H56: 45885 | I56: 2025/26 | J56: Sat | K56: Match Of The Day | L56: BBC 1 | M56: BBC | N56: 0.93194444 | O56: 0.98744213 | P56: 0.054965278 | Q56: 2605.8 | R56: 4.22 | S56: 35.2984 | T56: 3309.6 | U56: 207.1 | V56: 2.849 | W56: 61.6186 | X56: 277.5 | Y56: 2495.5 | Z56: 4.734 | AA56: 34.6496 | AB56: 3116.6 | AH56: =IF(AND(B56="Premier League",E56="Live"),_xlfn.XLOOKUP(_xlfn.TEXTJOIN(" vs ",,C56:D56),Calendar!G:G,Calendar!B:B),IF(AND(B56="Premier League",E56="Highlights"),_xlfn.XLOOKUP(H56,Calendar!O:O,Calendar!N:N,,-1),"")) -> Matchweek 01
A57: CDT | B57: Sky Bet Championship | C57: Ipswich Town | D57: Southampton | E57: Live | F57: 0.5 | H57: 45886 | I57: 2025/26 | J57: Sun | K57: Whistle-to-Whistle | L57: Sky Sports Main Event | M57: Sky Sports | N57: 0.50069444 | O57: 0.53402778 | P57: 0.033333333 | Q57: 313.04035 | R57: 0.50692105 | S57: 6.4710184 | T57: 494.4 | U57: 35.412281 | V57: 0.48719298 | W57: 30.474951 | X57: 98.4 | Y57: 291.49561 | Z57: 0.55299123 | AA57: 6.1910991 | AB57: 454.7 | AH57: =IF(AND(B57="Premier League",E57="Live"),_xlfn.XLOOKUP(_xlfn.TEXTJOIN(" vs ",,C57:D57),Calendar!G:G,Calendar!B:B),IF(AND(B57="Premier League",E57="Highlights"),_xlfn.XLOOKUP(H57,Calendar!O:O,Calendar!N:N,,-1),""))
